Failure # 1 (occurred at 2024-06-11_15-51-59)
The actor died because of an error raised in its creation task, [36mray::PPO.__init__()[39m (pid=74769, ip=10.159.28.40, actor_id=314a844508075f023b9a2af001000000, repr=PPO)
  File "/home/rigbac/Projects/ALPACA/env_RL_2/lib/python3.11/site-packages/ray/rllib/env/env_runner_group.py", line 239, in _setup
    self.add_workers(
  File "/home/rigbac/Projects/ALPACA/env_RL_2/lib/python3.11/site-packages/ray/rllib/env/env_runner_group.py", line 754, in add_workers
    raise result.get()
  File "/home/rigbac/Projects/ALPACA/env_RL_2/lib/python3.11/site-packages/ray/rllib/utils/actor_manager.py", line 497, in _fetch_result
    result = ray.get(r)
             ^^^^^^^^^^
           ^^^^^^^^^^^^^^^^^^^
           ^^^^^^^^^^^^^^^^^^^^^
                                  ^^^^^^^^^^^^^^^^^^^^^^^^^^^^^^^^^^^^^^^^^^^^^^^^
ray.exceptions.ActorDiedError: The actor died because of an error raised in its creation task, [36mray::RolloutWorker.__init__()[39m (pid=76505, ip=10.159.28.40, actor_id=b302a9c875cccb01bd23361b01000000, repr=<ray.rllib.evaluation.rollout_worker.RolloutWorker object at 0x14b4bc34b910>)
           ^^^^^^^^^^^^^^^^^^^^^^^^^^^^^^^^^^^^
           ^^^^^^^^^^^^^^^^^^^^^^^^^^^^^^^
  File "/home/rigbac/Projects/ALPACA/env_RL_2/lib/python3.11/site-packages/ray/rllib/evaluation/rollout_worker.py", line 407, in __init__
    self.env = env_creator(copy.deepcopy(self.env_context))
               ^^^^^^^^^^^^^^^^^^^^^^^^^^^^^^^^^^^^^^^^^^^^
  File "/home/rigbac/Projects/ALPACA/env_RL_2/lib/python3.11/site-packages/ray/rllib/env/utils/__init__.py", line 113, in _gym_env_creator
    env = gym.make(env_descriptor, **env_context)
          ^^^^^^^^^^^^^^^^^^^^^^^^^^^^^^^^^^^^^^^
  File "/home/rigbac/Projects/ALPACA/env_RL_2/lib/python3.11/site-packages/gymnasium/envs/registration.py", line 751, in make
    env_creator = load_env_creator(env_spec.entry_point)
                  ^^^^^^^^^^^^^^^^^^^^^^^^^^^^^^^^^^^^^^
  File "/home/rigbac/Projects/ALPACA/env_RL_2/lib/python3.11/site-packages/gymnasium/envs/registration.py", line 550, in load_env_creator
    mod = importlib.import_module(mod_name)
          ^^^^^^^^^^^^^^^^^^^^^^^^^^^^^^^^^
  File "/apps/spack/opt/gcc-12.3.0/python-3.11.6-3twidc7jth73nctkuwdshsdcqg4vrkcb/lib/python3.11/importlib/__init__.py", line 126, in import_module
    return _bootstrap._gcd_import(name[level:], package, level)
           ^^^^^^^^^^^^^^^^^^^^^^^^^^^^^^^^^^^^^^^^^^^^^^^^^^^^
  File "<frozen importlib._bootstrap>", line 1204, in _gcd_import
  File "<frozen importlib._bootstrap>", line 1176, in _find_and_load
  File "<frozen importlib._bootstrap>", line 1147, in _find_and_load_unlocked
  File "<frozen importlib._bootstrap>", line 690, in _load_unlocked
  File "<frozen importlib._bootstrap_external>", line 940, in exec_module
  File "<frozen importlib._bootstrap>", line 241, in _call_with_frames_removed
  File "/home/rigbac/Projects/ALPACA/env_RL_2/lib/python3.11/site-packages/gymnasium/envs/classic_control/Reactor-v8.py", line 38, in <module>
    class ReactorEnv(Env):
  File "/home/rigbac/Projects/ALPACA/env_RL_2/lib/python3.11/site-packages/gymnasium/envs/classic_control/Reactor-v8.py", line 135, in ReactorEnv
    os.mkdir('/scratch/rigbac/ThreadFiles/' + str(tid))
FileExistsError: [Errno 17] File exists: '/scratch/rigbac/ThreadFiles/22891248655232'

During handling of the above exception, another exception occurred:

[36mray::PPO.__init__()[39m (pid=74769, ip=10.159.28.40, actor_id=314a844508075f023b9a2af001000000, repr=PPO)
           ^^^^^^^^^^^^^^^^^^^^^^^^^^^^^^^^^^^^
           ^^^^^^^^^^^^^^^^^^^^^^^^^^^^^^^
  File "/home/rigbac/Projects/ALPACA/env_RL_2/lib/python3.11/site-packages/ray/rllib/algorithms/algorithm.py", line 554, in __init__
    super().__init__(
  File "/home/rigbac/Projects/ALPACA/env_RL_2/lib/python3.11/site-packages/ray/tune/trainable/trainable.py", line 158, in __init__
    self.setup(copy.deepcopy(self.config))
           ^^^^^^^^^^^^^^^^^^^^^^^^^^^^^^^
  File "/home/rigbac/Projects/ALPACA/env_RL_2/lib/python3.11/site-packages/ray/rllib/algorithms/algorithm.py", line 640, in setup
    self.workers = EnvRunnerGroup(
                   ^^^^^^^^^^^^^^^
  File "/home/rigbac/Projects/ALPACA/env_RL_2/lib/python3.11/site-packages/ray/rllib/env/env_runner_group.py", line 191, in __init__
    raise e.args[0].args[2]
FileExistsError: [Errno 17] File exists: '/scratch/rigbac/ThreadFiles/22891248655232'
